<?xml version="1.0" ?>
<!-- =================================================================================== -->
<!-- |    This document was autogenerated by xacro from mpo_500_base.urdf.xacro        | -->
<!-- |    EDITING THIS FILE BY HAND IS NOT RECOMMENDED                                 | -->
<!-- =================================================================================== -->
<robot name="mpo_500" xmlns:xacro="http://www.ros.org/wiki/xacro">
  <!-- Sensors -->
  <!-- Wheel Macro -->
  <!-- Materials -->
  <material name="Black">
    <color rgba="0.0 0.0 0.0 1.0"/>
  </material>
  <material name="Blue">
    <color rgba="0.0 0.0 0.8 1.0"/>
  </material>
  <material name="Green">
    <color rgba="0.0 0.8 0.0 1.0"/>
  </material>
  <material name="Grey">
    <color rgba="0.7 0.7 0.7 1.0"/>
  </material>
  <material name="Grey2">
    <color rgba="0.9 0.9 0.9 1.0"/>
  </material>
  <material name="Red">
    <color rgba="0.8 0.0 0.0 1.0"/>
  </material>
  <material name="White">
    <color rgba="1.0 1.0 1.0 1.0"/>
  </material>
  <!-- ROBOT -->
  <!-- BODY -->
  <link name="base_link">
    <inertial>
      <mass value="20"/>
      <origin xyz="0 0 0"/>
      <inertia ixx="1.0" ixy="0.0" ixz="0.0" iyy="1.0" iyz="0.0" izz="1.0"/>
    </inertial>
    <visual>
      <origin rpy="0 0 0" xyz="0. 0. 0.2"/>
      <geometry>
        <box size="0.68 0.41 0.25"/>
      </geometry>
      <material name="Grey"/>
    </visual>
    <collision>
      <origin rpy="0 0 0" xyz="0. 0. 0.2"/>
      <geometry>
        <box size="0.68 0.41 0.25"/>
      </geometry>
    </collision>
  </link>
  <!-- WHEELS -->
  <joint name="wheel_front_left_joint" type="continuous">
    <origin rpy="0 0 0" xyz="0.25 0.28 0.13"/>
    <axis xyz="0 1 0"/>
    <joint_properties damping="0.0" friction="0.0"/>
    <parent link="base_link"/>
    <child link="wheel_front_left_link"/>
  </joint>
  <link name="wheel_front_left_link" type="wheel">
    <inertial>
      <mass value="0.001"/>
      <origin rpy="0 0 0" xyz="0 0 0"/>
      <inertia ixx="0.0001" ixy="0" ixz="0" iyy="0.000001" iyz="0" izz="0.0001"/>
    </inertial>
    <visual>
      <origin rpy="1.59 0 0" xyz="0 0 0"/>
      <geometry>
        <cylinder length="0.1" radius="0.12"/>
      </geometry>
      <material name="Black"/>
    </visual>
    <collision>
      <origin rpy="1.59 0 0" xyz="0 0 0"/>
      <geometry>
        <cylinder length="0.1" radius="0.12"/>
      </geometry>
    </collision>
  </link>
  <joint name="wheel_front_right_joint" type="continuous">
    <origin rpy="0 0 0" xyz="0.25 -0.28 0.13"/>
    <axis xyz="0 1 0"/>
    <joint_properties damping="0.0" friction="0.0"/>
    <parent link="base_link"/>
    <child link="wheel_front_right_link"/>
  </joint>
  <link name="wheel_front_right_link" type="wheel">
    <inertial>
      <mass value="0.001"/>
      <origin rpy="0 0 0" xyz="0 0 0"/>
      <inertia ixx="0.0001" ixy="0" ixz="0" iyy="0.000001" iyz="0" izz="0.0001"/>
    </inertial>
    <visual>
      <origin rpy="1.59 0 0" xyz="0 0 0"/>
      <geometry>
        <cylinder length="0.1" radius="0.12"/>
      </geometry>
      <material name="Black"/>
    </visual>
    <collision>
      <origin rpy="1.59 0 0" xyz="0 0 0"/>
      <geometry>
        <cylinder length="0.1" radius="0.12"/>
      </geometry>
    </collision>
  </link>
  <joint name="wheel_back_left_joint" type="continuous">
    <origin rpy="0 0 0" xyz="-0.25 0.28 0.13"/>
    <axis xyz="0 1 0"/>
    <joint_properties damping="0.0" friction="0.0"/>
    <parent link="base_link"/>
    <child link="wheel_back_left_link"/>
  </joint>
  <link name="wheel_back_left_link" type="wheel">
    <inertial>
      <mass value="0.001"/>
      <origin rpy="0 0 0" xyz="0 0 0"/>
      <inertia ixx="0.0001" ixy="0" ixz="0" iyy="0.000001" iyz="0" izz="0.0001"/>
    </inertial>
    <visual>
      <origin rpy="1.59 0 0" xyz="0 0 0"/>
      <geometry>
        <cylinder length="0.1" radius="0.12"/>
      </geometry>
      <material name="Black"/>
    </visual>
    <collision>
      <origin rpy="1.59 0 0" xyz="0 0 0"/>
      <geometry>
        <cylinder length="0.1" radius="0.12"/>
      </geometry>
    </collision>
  </link>
  <joint name="wheel_back_right_joint" type="continuous">
    <origin rpy="0 0 0" xyz="-0.25 -0.28 0.13"/>
    <axis xyz="0 1 0"/>
    <joint_properties damping="0.0" friction="0.0"/>
    <parent link="base_link"/>
    <child link="wheel_back_right_link"/>
  </joint>
  <link name="wheel_back_right_link" type="wheel">
    <inertial>
      <mass value="0.001"/>
      <origin rpy="0 0 0" xyz="0 0 0"/>
      <inertia ixx="0.0001" ixy="0" ixz="0" iyy="0.000001" iyz="0" izz="0.0001"/>
    </inertial>
    <visual>
      <origin rpy="1.59 0 0" xyz="0 0 0"/>
      <geometry>
        <cylinder length="0.1" radius="0.12"/>
      </geometry>
      <material name="Black"/>
    </visual>
    <collision>
      <origin rpy="1.59 0 0" xyz="0 0 0"/>
      <geometry>
        <cylinder length="0.1" radius="0.12"/>
      </geometry>
    </collision>
  </link>
  <!-- Laser Scanner -->
  <joint name="laserfront_joint" type="fixed">
    <axis xyz="0 1 0"/>
    <origin rpy="0 0 0" xyz="0.39 0 0"/>
    <parent link="base_link"/>
    <child link="laserfront_link"/>
  </joint>
  <link name="laserfront_link" type="laser">
    <inertial>
      <mass value="0.001"/>
      <origin rpy="0 0 0" xyz="0 0 0"/>
      <inertia ixx="0.0001" ixy="0" ixz="0" iyy="0.000001" iyz="0" izz="0.0001"/>
    </inertial>
    <visual>
      <origin rpy="0 0 0" xyz="0 0 0"/>
      <geometry>
        <box size="0.001 0.001 0.001"/>
      </geometry>
      <material name="Red"/>
    </visual>
    <collision>
      <origin rpy="0 0 0" xyz="0 0 0"/>
      <geometry>
        <box size=".001 .001 .001"/>
      </geometry>
    </collision>
  </link>
  <joint name="laserback_joint" type="fixed">
    <axis xyz="0 1 0"/>
    <origin rpy="0 0 3.14" xyz="-0.39 0 0"/>
    <parent link="base_link"/>
    <child link="laserback_link"/>
  </joint>
  <link name="laserback_link" type="laser">
    <inertial>
      <mass value="0.001"/>
      <origin rpy="0 0 0" xyz="0 0 0"/>
      <inertia ixx="0.0001" ixy="0" ixz="0" iyy="0.000001" iyz="0" izz="0.0001"/>
    </inertial>
    <visual>
      <origin rpy="0 0 0" xyz="0 0 0"/>
      <geometry>
        <box size="0.001 0.001 0.001"/>
      </geometry>
      <material name="Red"/>
    </visual>
    <collision>
      <origin rpy="0 0 0" xyz="0 0 0"/>
      <geometry>
        <box size=".001 .001 .001"/>
      </geometry>
    </collision>
  </link>
</robot>

