<?xml version="1.0"?>
<robot xmlns:xacro="http://www.ros.org/wiki/xacro" name="mpo_500">
<!-- Sensors -->

<macro name="sick_s300_laser_v0" params="name parent *origin">
    <joint name="${name}_joint" type="fixed">
      <axis xyz="0 1 0" />
      <insert_block name="origin" />
      <parent link="${parent}"/>
      <child link="${name}_link"/>
    </joint>
    <link name="${name}_link" type="laser">
      <inertial>
        <mass value="0.001" />
        <origin xyz="0 0 0" rpy="0 0 0" />
        <inertia ixx="0.0001" ixy="0" ixz="0" iyy="0.000001" iyz="0" izz="0.0001" />
      </inertial>
      <visual>
        <origin xyz="0 0 0" rpy="0 0 0" />
        <geometry>
          <box size="0.001 0.001 0.001" />
        </geometry>
        <material name="Red" />
      </visual>
      <collision>
        <origin xyz="0 0 0" rpy="0 0 0" />
        <geometry>
          <box size=".001 .001 .001" />
        </geometry>
      </collision>
    </link>
  </macro>

<!-- Wheel Macro -->
<xacro:macro name="omni_wheel_250" params="name parent *origin">
 <joint name="${name}_joint" type="continuous">
  <insert_block name="origin" />
  <axis xyz="0 1 0" />
  <joint_properties damping="0.0" friction="0.0" />
  <parent link="${parent}" />
  <child link="${name}_link" />
 </joint>

 <link name="${name}_link" type="wheel">
  <inertial>
    <mass value="0.001" />
    <origin xyz="0 0 0" rpy="0 0 0" />
    <inertia ixx="0.0001" ixy="0" ixz="0" iyy="0.000001" iyz="0" izz="0.0001" />
  </inertial>

  <visual>
   <origin xyz="0 0 0" rpy="1.59 0 0" />
   <geometry>
	<cylinder radius="0.12" length="0.1"/>
   </geometry>
   <material name="Black" />
  </visual>

  <collision>
   <origin xyz="0 0 0" rpy="1.59 0 0" />
   <geometry>
	<cylinder radius="0.12" length="0.1"/>
   </geometry>
  </collision>
 </link>
</xacro:macro>

<!-- Materials -->
<material name="Black">
        <color rgba="0.0 0.0 0.0 1.0"/>
    </material>

    <material name="Blue">
        <color rgba="0.0 0.0 0.8 1.0"/>
    </material>

    <material name="Green">
        <color rgba="0.0 0.8 0.0 1.0"/>
    </material>

    <material name="Grey">
        <color rgba="0.7 0.7 0.7 1.0"/>
    </material>

    <material name="Grey2">
        <color rgba="0.9 0.9 0.9 1.0"/>
    </material>

    <material name="Red">
        <color rgba="0.8 0.0 0.0 1.0"/>
    </material>

    <material name="White">
        <color rgba="1.0 1.0 1.0 1.0"/>
    </material>

<!-- ROBOT -->


<!-- BODY -->
  <link name="base_link">
    <inertial>
      <mass value="20" />
      <origin xyz="0 0 0" />
      <inertia ixx="1.0" ixy="0.0" ixz="0.0"
               iyy="1.0" iyz="0.0" 
               izz="1.0" />
    </inertial>
    <visual>
       <origin xyz="0. 0. 0.2" rpy="0 0 0" />
       <geometry><box size="0.68 0.41 0.25"/></geometry>
       <material name="Grey" />
    </visual>
    <collision>
       <origin xyz="0. 0. 0.2" rpy="0 0 0" />
       <geometry><box size="0.68 0.41 0.25"/></geometry>
    </collision>
  </link>

<!-- WHEELS -->
  <omni_wheel_250 name="wheel_front_left" parent="base_link">
     <origin xyz="0.25 0.28 0.13" rpy="0 0 0" />
  </omni_wheel_250>
        
  <omni_wheel_250 name="wheel_front_right" parent="base_link">
     <origin xyz="0.25 -0.28 0.13" rpy="0 0 0" />
  </omni_wheel_250>

  <omni_wheel_250 name="wheel_back_left" parent="base_link">
      <origin xyz="-0.25 0.28 0.13" rpy="0 0 0" />
  </omni_wheel_250>
        
  <omni_wheel_250 name="wheel_back_right" parent="base_link">
      <origin xyz="-0.25 -0.28 0.13" rpy="0 0 0" />
  </omni_wheel_250>

<!-- Laser Scanner -->
  <sick_s300_laser_v0 name="laserfront" parent="base_link">
    <origin xyz="0.39 0 0" rpy="0 0 0" />
  </sick_s300_laser_v0>
  <sick_s300_laser_v0 name="laserback" parent="base_link">
    <origin xyz="-0.39 0 0" rpy="0 0 3.14" />
  </sick_s300_laser_v0>

</robot>
