<?xml version="1.0"?>

<xacro:macro name="omni_wheel_250" params="suffix parent *origin">
 <joint name="${suffix}_joint" type="continuous">
  <insert_block name="origin" />
  <axis xyz="0 1 0" />
  <joint_properties damping="0.0" friction="0.0" />
  <parent link="${parent}_link" />
  <child link="${suffix}_link" />
 </joint>

 <link name="${suffix}_link" type="wheel">
  <inertial>
    <mass value="0.001" />
    <origin xyz="0 0 0" rpy="0 0 0" />
    <inertia ixx="0.0001" ixy="0" ixz="0" iyy="0.000001" iyz="0" izz="0.0001" />
  </inertial>

  <visual>
   <origin xyz="0 0 0" rpy="1.59 0 0" />
   <geometry>
	<cylinder radius="0.12" length="0.1"/>
   </geometry>
   <material name="Black" />
  </visual>

  <collision>
   <origin xyz="0 0 0" rpy="1.59 0 0" />
   <geometry>
	<cylinder radius="0.12" length="0.1"/>
   </geometry>
  </collision>
 </link>
</xacro:macro>



